Workbook
Name CapitalCost: FBCA!$B$10
Name DiscountedPBP: FBCA!$C$57
Name DiscountRate: FBCA!$B$9
Name EfficiencyDerate: FBCA!$B$12
Name FBCR: FBCA!$C$55
Name FIRR: FBCA!$C$56
Name FNPV: FBCA!$C$54
Name Generation: FBCA!$B$11
Name ModuleDegradation: FBCA!$B$14
Name OandMescalation: FBCA!$B$16
Name OandMyr0: FBCA!$B$15
Name ProjectDuration: FBCA!$B$6
Name Tariff: FBCA!$B$13

Sheet FBCA
A1: Financial Benefit - Cost Analysis (FBCA) – Siyambalanduwa 100 MW Solar
A3: 1. Assumptions & Parameters
A5: Assumptions
A6: Project duration (years) | B6: 20
A8: Parameters
A9: Discount rate (r) | B9: =Sensitivity_Analysis!C10 -> 0.09
A10: Total CapEx (LKR mn) | B10: =Sensitivity_Analysis!C6 -> 14833.652
A11: Annual generation (GWh) for yr1 | B11: =Sensitivity_Analysis!C9 -> 180
A12: Efficiency derate (Performance Ratio) | B12: 0.85
A13: Tariff (LKR/kWh) | B13: =Sensitivity_Analysis!C5 -> 14
A14: Module degradation (per year) | B14: 0.007
A15: O&M % of CapEx for year 0 | B15: =Sensitivity_Analysis!C7 -> 0.01
A16: O&M escalation per year | B16: =Sensitivity_Analysis!C8 -> 0.03
A18: 2. Cash Flow Analysis
A20: Year | B20: Total | C20: 0 | D20: 1 | E20: 2 | F20: 3 | G20: 4 | H20: 5 | I20: 6 | J20: 7 | K20: 8 | L20: 9 | M20: 10 | N20: 11 | O20: 12 | P20: 13 | Q20: 14 | R20: 15 | S20: 16 | T20: 17 | U20: 18 | V20: 19 | W20: 20
A21: Financial Benefit
A22: Tariff revenue | B22: =SUM(C22:W22) -> 40107.311 | C22: 0 | D22: =(Generation*((1-ModuleDegradation)^(D20-1))*EfficiencyDerate*Tariff) -> 2142 | E22: =(Generation*((1-ModuleDegradation)^(E20-1))*EfficiencyDerate*Tariff) -> 2127.006 | F22: =(Generation*((1-ModuleDegradation)^(F20-1))*EfficiencyDerate*Tariff) -> 2112.117 | G22: =(Generation*((1-ModuleDegradation)^(G20-1))*EfficiencyDerate*Tariff) -> 2097.3321 | H22: =(Generation*((1-ModuleDegradation)^(H20-1))*EfficiencyDerate*Tariff) -> 2082.6508 | I22: =(Generation*((1-ModuleDegradation)^(I20-1))*EfficiencyDerate*Tariff) -> 2068.0723 | J22: =(Generation*((1-ModuleDegradation)^(J20-1))*EfficiencyDerate*Tariff) -> 2053.5958 | K22: =(Generation*((1-ModuleDegradation)^(K20-1))*EfficiencyDerate*Tariff) -> 2039.2206 | ... W22: =(Generation*((1-ModuleDegradation)^(W20-1))*EfficiencyDerate*Tariff) -> 1874.3694
A23: TOTAL FINANCIAL BENEFIT | B23: =SUM(C23:W23) -> 40107.311 | C23: =C22 -> 0 | D23: =D22 -> 2142 | E23: =E22 -> 2127.006 | F23: =F22 -> 2112.117 | G23: =G22 -> 2097.3321 | H23: =H22 -> 2082.6508 | I23: =I22 -> 2068.0723 | J23: =J22 -> 2053.5958 | ... W23: =W22 -> 1874.3694
A24: Financial costs
A25: Capital costs | B25: =SUM(C25:W25) -> 14833.652 | C25: =CapitalCost -> 14833.652 | D25: 0 | E25: 0 | F25: 0 | G25: 0 | H25: 0 | I25: 0 | J25: 0 | K25: 0 | L25: 0 | M25: 0 | N25: 0 | O25: 0 | P25: 0 | Q25: 0 | R25: 0 | S25: 0 | T25: 0 | U25: 0 | V25: 0 | W25: 0
A26: O&M costs | B26: =SUM(C26:W26) -> 3985.8578 | C26: 0 | D26: =(CapitalCost*OandMyr0*(1+OandMescalation)^(D20-1)) -> 148.33652 | E26: =(CapitalCost*OandMyr0*(1+OandMescalation)^(E20-1)) -> 152.78662 | F26: =(CapitalCost*OandMyr0*(1+OandMescalation)^(F20-1)) -> 157.37021 | G26: =(CapitalCost*OandMyr0*(1+OandMescalation)^(G20-1)) -> 162.09132 | H26: =(CapitalCost*OandMyr0*(1+OandMescalation)^(H20-1)) -> 166.95406 | I26: =(CapitalCost*OandMyr0*(1+OandMescalation)^(I20-1)) -> 171.96268 | J26: =(CapitalCost*OandMyr0*(1+OandMescalation)^(J20-1)) -> 177.12156 | K26: =(CapitalCost*OandMyr0*(1+OandMescalation)^(K20-1)) -> 182.43521 | ... W26: =(CapitalCost*OandMyr0*(1+OandMescalation)^(W20-1)) -> 260.10899
A27: TOTAL FINANCIAL COSTS | B27: =SUM(C27:W27) -> 18819.51 | C27: =SUM(C25:C26) -> 14833.652 | D27: =SUM(D25:D26) -> 148.33652 | E27: =SUM(E25:E26) -> 152.78662 | F27: =SUM(F25:F26) -> 157.37021 | G27: =SUM(G25:G26) -> 162.09132 | H27: =SUM(H25:H26) -> 166.95406 | I27: =SUM(I25:I26) -> 171.96268 | J27: =SUM(J25:J26) -> 177.12156 | ... W27: =SUM(W25:W26) -> 260.10899
A29: Net Financial Benefit | B29: =SUM(C29:W29) -> 21287.801 | C29: =C23-C27 -> -14833.652 | D29: =D23-D27 -> 1993.6635 | E29: =E23-E27 -> 1974.2194 | F29: =F23-F27 -> 1954.7467 | G29: =G23-G27 -> 1935.2408 | H29: =H23-H27 -> 1915.6968 | I29: =I23-I27 -> 1896.1096 | J29: =J23-J27 -> 1876.4742 | ... W29: =W23-W27 -> 1614.2604
A31: 3.Present Value Calculations
A33: PV of Benefits | C33: =C23/(1+DiscountRate)^C20 -> 0 | D33: =D23/(1+DiscountRate)^D20 -> 1965.1376 | E33: =E23/(1+DiscountRate)^E20 -> 1790.2584 | F33: =F23/(1+DiscountRate)^F20 -> 1630.9418 | G33: =G23/(1+DiscountRate)^G20 -> 1485.803 | H33: =H23/(1+DiscountRate)^H20 -> 1353.5801 | I33: =I23/(1+DiscountRate)^I20 -> 1233.1239 | J33: =J23/(1+DiscountRate)^J20 -> 1123.3872 | ... W33: =W23/(1+DiscountRate)^W20 -> 334.4454
A34: PV of Costs | C34: =C27/(1+DiscountRate)^C20 -> 14833.652 | D34: =D27/(1+DiscountRate)^D20 -> 136.08855 | E34: =E27/(1+DiscountRate)^E20 -> 128.59744 | F34: =F27/(1+DiscountRate)^F20 -> 121.51868 | G34: =G27/(1+DiscountRate)^G20 -> 114.82958 | H34: =H27/(1+DiscountRate)^H20 -> 108.50868 | I34: =I27/(1+DiscountRate)^I20 -> 102.53573 | J34: =J27/(1+DiscountRate)^J20 -> 96.89156 | ... W34: =W27/(1+DiscountRate)^W20 -> 46.411478
A35: PV of Net Benefits (LKR mn) | C35: =C29/(1+DiscountRate)^C20 -> -14833.652 | D35: =D29/(1+DiscountRate)^D20 -> 1829.0491 | E35: =E29/(1+DiscountRate)^E20 -> 1661.661 | F35: =F29/(1+DiscountRate)^F20 -> 1509.4231 | G35: =G29/(1+DiscountRate)^G20 -> 1370.9734 | H35: =H29/(1+DiscountRate)^H20 -> 1245.0714 | I35: =I29/(1+DiscountRate)^I20 -> 1130.5882 | J35: =J29/(1+DiscountRate)^J20 -> 1026.4956 | ... W35: =W29/(1+DiscountRate)^W20 -> 288.03392
A36: Cumulative PV Net | C36: =C35 -> -14833.652 | D36: =C36+D35 -> -13004.603 | E36: =D36+E35 -> -11342.942 | F36: =E36+F35 -> -9833.5188 | G36: =F36+G35 -> -8462.5454 | H36: =G36+H35 -> -7217.474 | I36: =H36+I35 -> -6086.8858 | J36: =I36+J35 -> -5060.3902 | K36: =J36+K35 -> -4128.5322 | ... W36: =V36+W35 -> 2149.5218
A38: 4.Supporting Payback Calculations
A40: Cumulative PV Net (discounted) | C40: =C36 -> -14833.652 | D40: =D36 -> -13004.603 | E40: =E36 -> -11342.942 | F40: =F36 -> -9833.5188 | G40: =G36 -> -8462.5454 | H40: =H36 -> -7217.474 | I40: =I36 -> -6086.8858 | J40: =J36 -> -5060.3902 | ... W40: =W36 -> 2149.5218
A41: Last Negative Year | B41: {=MAX(IF(C40:W40<0,COLUMN(C40:W40)-COLUMN(C40)))} -> 14
A42: Deficit at Last Negative Year | B42: {=INDEX(C40:W40,B41+1)} -> -93.573976
A43: Next Year Net Benefit | B43: {=IF(B41=ProjectDuration,"-",INDEX(C40:W40,B41+2))} -> 377.80799
A44: PBP Index | B44: =IF(B41=ProjectDuration,">"&ProjectDuration,B41+ABS(B42)/(ABS(B42)+B43)) -> 14.19851
A46: Cumulative Net (undiscounted) | C46: =C29 -> -14833.652 | D46: =C46+D29 -> -12839.989 | E46: =D46+E29 -> -10865.769 | F46: =E46+F29 -> -8911.0224 | G46: =F46+G29 -> -6975.7816 | H46: =G46+H29 -> -5060.0848 | I46: =H46+I29 -> -3163.9752 | J46: =I46+J29 -> -1287.5011 | K46: =J46+K29 -> 569.28432 | ... W46: =V46+W29 -> 21287.801
A47: Last Negative Year | B47: {=MAX(IF(C46:W46<0,COLUMN(C46:W46)-COLUMN(C46)))} -> 7
A48: Deficit at Last Negative Year | B48: {=INDEX(C46:W46,B47+1)} -> -1287.5011
A49: Next Year Net Benefit | B49: {=IF(B47=ProjectDuration,"-",INDEX(C46:W46,B47+2))} -> 569.28432
A50: Simple PBP Index | B50: =IF(B47=ProjectDuration,">"&ProjectDuration,B47+ABS(B48)/(ABS(B48)+B49)) -> 7.6934033
A52: 5.Results Summary
...

Sheet Sensitivity_Analysis
A1: Financial Sensitivity Analysis – Siyambalanduwa 100 MW Solar
A3: Base Case Inputs (Linked to Financial BCA Model)
A5: Tariff (LKR/kWh) | C5: 14
A6: Capital Cost (LKR Mn) | C6: 14833.652
A7: O&M % of CapEx for year 0 | C7: 0.01
A8: O&M escalation per year | C8: 0.03
A9: Annual generation (GWh) for yr1 | C9: 180
A10: Discount Rate (%) | C10: 0.09
A12: (a) Tariff Sensitivity
A14: Test deltas | B14: Tariff (LKR/kWh)
A15: -0.1 | B15: =Tariff*(1+A15) -> 12.6
A16: 0 | B16: =Tariff*(1+A16) -> 14
A17: 0.1 | B17: =Tariff*(1+A17) -> 15.4
A19: Tariff (LKR/kWh) | B19: FNPV (LKR M) | C19: FIRR (%) | D19: FPBP (yrs) | E19: FBCR
A20: 14(Base) | B20: =FNPV -> 2149.5218 | C20: =FIRR -> 0.11066572 | D20: =DiscountedPBP -> 14.2 | E20: =FBCR -> 1.1302015
A21: 12.6 | B21: 283.64989 | C21: 0.09278937 | D21: 18.9 | E21: 1.0171813
A22: 14 | B22: 2149.5218 | C22: 0.11066572 | D22: 14.2 | E22: 1.1302015
A23: 15.4 | B23: 4015.3936 | C23: 0.12786429 | D23: 11.57 | E23: 1.2432216
A26: (b) Capital Cost Sensitivity
A28: ΔCapEx | B28: CapEx (LKR Mn)
A29: -0.15 | B29: =CapitalCost*(1+A29) -> 12608.604
A30: 0 | B30: =CapitalCost*(1+A30) -> 14833.652
A31: 0.15 | B31: =CapitalCost*(1+A31) -> 17058.7
A33: CapEx (LKR Mn) | B33: FNPV (LKR M) | C33: FIRR (%) | D33: FPBP (yrs) | E33: FBCR
A34: 14833.652(Base) | B34: =FNPV -> 2149.5218 | C34: =FIRR -> 0.11066572 | D34: =DiscountedPBP -> 14.2 | E34: =FBCR -> 1.1302015
A35: 12608.604 | B35: 4625.9013 | C35: 0.14065574 | D35: 10.18 | E35: 1.3296488
A36: 14833.652 | B36: 2149.5218 | C36: 0.11066572 | D36: 14.2 | E36: 1.1302015
A37: 17058.7 | B37: -326.85779 | C37: 0.087183534 | D37: >20 | E37: 0.98278389
A40: (c) O&M Cost Sensitivity
A42: O&M % of CapEx | B42: FNPV (LKR M) | C42: FIRR (%) | D42: FPBP (yrs) | E42: FBCR
A43: 1% (Base) | B43: =FNPV -> 2149.5218 | C43: =FIRR -> 0.11066572 | D43: =DiscountedPBP -> 14.2 | E43: =FBCR -> 1.1302015
A44: 0.0098 | B44: 2183.0327 | C44: 0.11097377 | D44: 14.14 | E44: 1.1325003
A45: 0.01 | B45: 2149.5218 | C45: 0.11066572 | D45: 14.2 | E45: 1.1302015
A46: 0.012 | B46: 1814.4128 | C46: 0.10756374 | D46: 14.79 | E46: 1.1077167
A49: (d) O&M Escalation Sensitivity
A51: O&M escalation | B51: FNPV (LKR M) | C51: FIRR (%) | D51: FPBP (yrs) | E51: FBCR
A52: 3% (Base) | B52: =FNPV -> 2149.5218 | C52: =FIRR -> 0.11066572 | D52: =DiscountedPBP -> 14.2 | E52: =FBCR -> 1.1302015
A53: 0.02 | B53: 2267.8276 | C53: 0.11166887 | D53: 14.05 | E53: 1.138359
A54: 0.03 | B54: 2149.5218 | C54: 0.11066572 | D54: 14.2 | E54: 1.1302015
A55: 0.05 | B55: 1872.3287 | C55: 0.10828334 | D55: 14.56 | E55: 1.1115385
...
