Workbook
Name AvoidFuelCost: EBCA!$B$12
Name CapitalCost: EBCA!$B$24
Name CO2Avoided: EBCA!$B$9
Name DiscountedEPBP: EBCA!$C$85
Name DiscountedPBP: [1]FBCA!$C$57
Name DiscountRate: EBCA!$B$5
Name EBCR: EBCA!$C$83
Name EfficiencyDerate: EBCA!$B$14
Name EIRR: EBCA!$C$84
Name EmpIncomePerJob: EBCA!$B$19
Name EmpJobsAfteryr0: EBCA!$B$17
Name EmpJobsForyr0: EBCA!$B$18
Name ENPV: EBCA!$C$82
Name EnvBenifit: EBCA!$B$11
Name EnvImpactCostyr0: EBCA!$B$21
Name FBCR: [1]FBCA!$C$55
Name FIRR: [1]FBCA!$C$56
Name FNPV: [1]FBCA!$C$54
Name Generation: EBCA!$B$13
Name LossOfRoyaltyRevenue: EBCA!$B$20
Name ModuleDegradation: EBCA!$B$16
Name OandMescalation: EBCA!$B$22
Name OandMyr1: EBCA!$B$23
Name ShadowExchRateFact: EBCA!$B$8
Name ShadWageRateFac: EBCA!$B$7
Name SimpleEPBP: EBCA!$C$86
Name SocialCostOfCarbon: EBCA!$B$10
Name StandConvFact: EBCA!$B$6
Name Tariff: EBCA!$B$15

Sheet EBCA
A1: Economic Benefit - Cost Analysis (EBCA) – Siyambalanduwa 100 MW Solar
A3: 1. Assumptions & Parameters
A5: Economic discount rate (real) | B5: =Sensitivity_Analysis!C5 -> 0.09
A6: Standard Conversion Factor (SCF) | B6: =Sensitivity_Analysis!C6 -> 0.9
A7: Shadow Wage Rate Factor (SWRF) | B7: =Sensitivity_Analysis!C7 -> 0.8
A8: Shadow Exchange Rate Factor (SERF) | B8: =Sensitivity_Analysis!C8 -> 1.1
A9: CO₂ avoided (ton/year) | B9: 147582
A10: Social cost of carbon (LKR/ton) | B10: =Sensitivity_Analysis!C9 -> 10000
A11: Environmental benefit (LKR mn/year) | B11: =B9*B10/1000000 -> 1475.82
A12: Avoided fuel cost (LKR/kWh) | B12: =Sensitivity_Analysis!C10 -> 19
A13: Annual generation (GWh) (Year 1) | B13: =Sensitivity_Analysis!C11 -> 180
A14: Efficiency derate (Performance Ratio) | B14: 0.85
A15: Tariff (LKR/kWh) | B15: 14
A16: Module degradation (per year) | B16: 0.007
A17: Employment (jobs) after year 0 | B17: =Sensitivity_Analysis!C12 -> 100
A18: Employment (jobs) for year 0 | B18: =Sensitivity_Analysis!C13 -> 1000
A19: Employment income per job (LKR mn/yr) | B19: =Sensitivity_Analysis!C14 -> 1
A20: Loss of royalty revenue (LKR mn/yr) | B20: =Sensitivity_Analysis!C15 -> 15
A21: Environmental impact cost Year 0 (LKR mn) | B21: =Sensitivity_Analysis!C16 -> 30
A22: O&M escalation (per year) | B22: =Sensitivity_Analysis!C17 -> 0.05
A23: O&M % of CapEx (financial) Year 1 | B23: =Sensitivity_Analysis!C18 -> 0.01
A24: CAPEX total (financial, LKR mn) | B24: =Sensitivity_Analysis!C19 -> 14833.65
A26: 2. Conversion of Financial Costs to Economic Costs
A28: Item | B28: Financial | C28: Split | D28: Conv | E28: Economic
A29: CAPEX
A30: Foreign component | B30: =B24 -> 14833.65 | C30: 0.6 | D30: =B8 -> 1.1 | E30: =B30*C30*D30 -> 9790.209
A31: Local goods/services | B31: =B24 -> 14833.65 | C31: 0.3 | D31: =B6 -> 0.9 | E31: =B31*C31*D31 -> 4005.0855
A32: Local labour | B32: =B24 -> 14833.65 | C32: 0.1 | D32: =B7 -> 0.8 | E32: =B32*C32*D32 -> 1186.692
A33: Total CAPEX (Economic) | E33: =SUM(E30:E32) -> 14981.986
A34: O&M
A35: Foreign content (yr 1) | B35: =B$24*B$23 -> 148.3365 | C35: 0.2 | D35: =B8 -> 1.1 | E35: =B35*C35*D35 -> 32.63403
A36: Local goods (yr 1) | B36: =B$24*B$23 -> 148.3365 | C36: 0.5 | D36: =B6 -> 0.9 | E36: =B36*C36*D36 -> 66.751425
A37: Local labour (yr 1) | B37: =B$24*B$23 -> 148.3365 | C37: 0.3 | D37: =B7 -> 0.8 | E37: =B37*C37*D37 -> 35.60076
A38: Total O&M (Economic, yr 1) | E38: =SUM(E35:E37) -> 134.98622
A40: 3. Economic Cash Flow Analysis
A42: Year | B42: Total | C42: 0 | D42: 1 | E42: 2 | F42: 3 | G42: 4 | H42: 5 | I42: 6 | J42: 7 | K42: 8 | L42: 9 | M42: 10 | N42: 11 | O42: 12 | P42: 13 | Q42: 14 | R42: 15 | S42: 16 | T42: 17 | U42: 18 | V42: 19 | W42: 20
A43: Energy (GWh) | B43: =SUM(C43:W43) -> 3370.3623 | C43: 0 | D43: =B13 -> 180 | E43: =D43*(1-$B$16) -> 178.74 | F43: =E43*(1-$B$16) -> 177.48882 | G43: =F43*(1-$B$16) -> 176.2464 | H43: =G43*(1-$B$16) -> 175.01267 | I43: =H43*(1-$B$16) -> 173.78758 | J43: =I43*(1-$B$16) -> 172.57107 | K43: =J43*(1-$B$16) -> 171.36307 | L43: =K43*(1-$B$16) -> 170.16353 | ... W43: =V43*(1-$B$16) -> 157.51003
A44: Economic Benefit
A45: Tariff revenue (LKR mn) | B45: =SUM(C45:W45) -> 40107.311 | C45: 0 | D45: =$B$13*((1-$B$16)^(D42-1))*$B$14*$B$15 -> 2142 | E45: =$B$13*((1-$B$16)^(E42-1))*$B$14*$B$15 -> 2127.006 | F45: =$B$13*((1-$B$16)^(F42-1))*$B$14*$B$15 -> 2112.117 | G45: =$B$13*((1-$B$16)^(G42-1))*$B$14*$B$15 -> 2097.3321 | H45: =$B$13*((1-$B$16)^(H42-1))*$B$14*$B$15 -> 2082.6508 | I45: =$B$13*((1-$B$16)^(I42-1))*$B$14*$B$15 -> 2068.0723 | J45: =$B$13*((1-$B$16)^(J42-1))*$B$14*$B$15 -> 2053.5958 | K45: =$B$13*((1-$B$16)^(K42-1))*$B$14*$B$15 -> 2039.2206 | ... W45: =$B$13*((1-$B$16)^(W42-1))*$B$14*$B$15 -> 1874.3694
A46: Avoided Fuel (LKR mn) | B46: =SUM(C46:W46) -> 64036.883 | C46: =C43*$B$12 -> 0 | D46: =D43*$B$12 -> 3420 | E46: =E43*$B$12 -> 3396.06 | F46: =F43*$B$12 -> 3372.2876 | G46: =G43*$B$12 -> 3348.6816 | H46: =H43*$B$12 -> 3325.2408 | I46: =I43*$B$12 -> 3301.9641 | J46: =J43*$B$12 -> 3278.8504 | ... W46: =W43*$B$12 -> 2992.6907
...

Sheet Sensitivity_Analysis
A1: Economic Sensitivity Analysis – Siyambalanduwa 100 MW Solar
A3: Base Case Inputs (Linked to Economic BCA Model)
A5: Economic discount rate (real) | C5: 0.09
A6: Standard Conversion Factor (SCF) | C6: 0.9
A7: Shadow Wage Rate Factor (SWRF) | C7: 0.8
A8: Shadow Exchange Rate Factor (SERF) | C8: 1.1
A9: Social cost of carbon (LKR/ton) | C9: 10000
A10: Avoided fuel cost (LKR/kWh) | C10: 19
A11: Annual generation (GWh) (Year 1) | C11: 180
A12: Employment (jobs) after year 0 | C12: 100
A13: Employment (jobs) for year 0 | C13: 1000
A14: Employment income per job (LKR mn/yr) | C14: 1
A15: Loss of royalty revenue (LKR mn/yr) | C15: 15
A16: Environmental impact cost Year 0 (LKR mn) | C16: 30
... A19: CAPEX total (financial, LKR mn) | C19: 14833.65
A22: (a) Avoided Fuel Cost Sensitivity
A24: Avoided Fuel Cost (LKR/kWh) | B24: ENPV (LKR mn) | C24: EIRR (%) | D24: EPBP (yrs) | E24: EBCR
A25: 19 (Base) | B25: =ENPV -> 28387.199 | C25: =EIRR -> 0.33947035 | D25: =DiscountedEPBP -> 3.53 | E25: =EBCR -> 2.6908235
A26: 15.2 | B26: 22428.952 | C26: 0.28996086 | D26: 4.23 | E26: 2.3359332
A27: 19 | B27: 28387.199 | C27: 0.33947035 | D27: 3.53 | E27: 2.6908235
A28: 22.8 | B28: 34345.445 | C28: 0.38864783 | D28: 3.02 | E28: 3.0457139
A31: (b) Annual Generation Sensitivity
A33: Annual Generation (GWh) | B33: ENPV (LKR mn) | C33: EIRR (%) | D33: EPBP (yrs) | E33: EBCR
A34: 180 (Base) | B34: =ENPV -> 28387.199 | C34: =EIRR -> 0.33947035 | D34: =DiscountedEPBP -> 3.53 | E34: =EBCR -> 2.6908235
A35: 162 | B35: 25408.075 | C35: 0.31477139 | D35: 3.84 | E35: 2.5133783
A36: 180 | B36: 28387.199 | C36: 0.33947035 | D36: 3.53 | E36: 2.6908235
A37: 198 | B37: 31366.322 | C37: 0.36408845 | D37: 3.25 | E37: 2.8682687
A40: (c) CapEx Sensitivity
A42: CapEx (LKR Mn) | B42: ENPV (LKR mn) | C42: EIRR (%) | D42: EPBP (yrs) | E42: EBCR
A43: 14833.65 (Base) | B43: =ENPV -> 28387.199 | C43: =EIRR -> 0.33947035 | D43: =DiscountedEPBP -> 3.53 | E43: =EBCR -> 2.6908235
A44: 12608.603 | B44: 30901.045 | C44: 0.40825618 | D44: 2.86 | E44: 3.1646768
A45: 14833.65 | B45: 28387.199 | C45: 0.33947035 | D45: 3.53 | E45: 2.6908235
A46: 17058.697 | B46: 25873.352 | C46: 0.28922508 | D46: 4.24 | E46: 2.340392
A49: (d) Economic Discount Rate Sensitivity
A51: Economic Discount Rate | B51: ENPV (LKR mn) | C51: EIRR (%) | D51: EPBP (yrs) | E51: EBCR
A52: 9% (Base) | B52: =ENPV -> 28387.199 | C52: =EIRR -> 0.33947035 | D52: =DiscountedEPBP -> 3.53 | E52: =EBCR -> 2.6908235
A53: 0.07 | B53: 35002.86 | C53: 0.33947035 | D53: 3.37 | E53: 3.042943
A54: 0.09 | B54: 28387.199 | C54: 0.33947035 | D54: 3.53 | E54: 2.6908235
A55: 0.11 | B55: 23107.782 | C55: 0.33947035 | D55: 3.7 | E55: 2.398661
A58: (e) Social Cost of Carbon Sensitivity
...
